Traceback (most recent call last):
  File "/opt/hostedtoolcache/Python/3.8.16/x64/lib/python3.8/site-packages/jupyter_cache/executors/utils.py", line 58, in single_nb_execution
    executenb(
  File "/opt/hostedtoolcache/Python/3.8.16/x64/lib/python3.8/site-packages/nbclient/client.py", line 1204, in execute
    return NotebookClient(nb=nb, resources=resources, km=km, **kwargs).execute()
  File "/opt/hostedtoolcache/Python/3.8.16/x64/lib/python3.8/site-packages/nbclient/util.py", line 84, in wrapped
    return just_run(coro(*args, **kwargs))
  File "/opt/hostedtoolcache/Python/3.8.16/x64/lib/python3.8/site-packages/nbclient/util.py", line 62, in just_run
    return loop.run_until_complete(coro)
  File "/opt/hostedtoolcache/Python/3.8.16/x64/lib/python3.8/asyncio/base_events.py", line 616, in run_until_complete
    return future.result()
  File "/opt/hostedtoolcache/Python/3.8.16/x64/lib/python3.8/site-packages/nbclient/client.py", line 663, in async_execute
    await self.async_execute_cell(
  File "/opt/hostedtoolcache/Python/3.8.16/x64/lib/python3.8/site-packages/nbclient/client.py", line 965, in async_execute_cell
    await self._check_raise_for_error(cell, cell_index, exec_reply)
  File "/opt/hostedtoolcache/Python/3.8.16/x64/lib/python3.8/site-packages/nbclient/client.py", line 862, in _check_raise_for_error
    raise CellExecutionError.from_cell_and_msg(cell, exec_reply_content)
nbclient.exceptions.CellExecutionError: An error occurred while executing the following cell:
------------------
exmol.lime_explain(space, "ecfp")
s1_ecfp = exmol.text_explain(space, "ecfp")
explanation = exmol.text_explain_generate(s1_ecfp, "aqueous solubility")
print(explanation)
------------------

[0;31m---------------------------------------------------------------------------[0m
[0;31mValidationError[0m                           Traceback (most recent call last)
Cell [0;32mIn[17], line 3[0m
[1;32m      1[0m exmol[38;5;241m.[39mlime_explain(space, [38;5;124m"[39m[38;5;124mecfp[39m[38;5;124m"[39m)
[1;32m      2[0m s1_ecfp [38;5;241m=[39m exmol[38;5;241m.[39mtext_explain(space, [38;5;124m"[39m[38;5;124mecfp[39m[38;5;124m"[39m)
[0;32m----> 3[0m explanation [38;5;241m=[39m [43mexmol[49m[38;5;241;43m.[39;49m[43mtext_explain_generate[49m[43m([49m[43ms1_ecfp[49m[43m,[49m[43m [49m[38;5;124;43m"[39;49m[38;5;124;43maqueous solubility[39;49m[38;5;124;43m"[39;49m[43m)[49m
[1;32m      4[0m [38;5;28mprint[39m(explanation)

File [0;32m/opt/hostedtoolcache/Python/3.8.16/x64/lib/python3.8/site-packages/exmol/exmol.py:1393[0m, in [0;36mtext_explain_generate[0;34m(text_explanations, property_name, llm, single)[0m
[1;32m   1391[0m prompt [38;5;241m=[39m prompt_template[38;5;241m.[39mformat([38;5;28mproperty[39m[38;5;241m=[39mproperty_name, text[38;5;241m=[39mtext)
[1;32m   1392[0m [38;5;28;01mif[39;00m llm [38;5;129;01mis[39;00m [38;5;28;01mNone[39;00m:
[0;32m-> 1393[0m     llm [38;5;241m=[39m [43mllms[49m[38;5;241;43m.[39;49m[43mOpenAI[49m[43m([49m[43mtemperature[49m[38;5;241;43m=[39;49m[38;5;241;43m0.05[39;49m[43m)[49m
[1;32m   1394[0m [38;5;28;01mreturn[39;00m llm(prompt)

File [0;32m/opt/hostedtoolcache/Python/3.8.16/x64/lib/python3.8/site-packages/pydantic/main.py:341[0m, in [0;36mpydantic.main.BaseModel.__init__[0;34m()[0m

[0;31mValidationError[0m: 1 validation error for OpenAI
__root__
  Did not find openai_api_key, please add an environment variable `OPENAI_API_KEY` which contains it, or pass  `openai_api_key` as a named parameter. (type=value_error)
ValidationError: 1 validation error for OpenAI
__root__
  Did not find openai_api_key, please add an environment variable `OPENAI_API_KEY` which contains it, or pass  `openai_api_key` as a named parameter. (type=value_error)

